2020-06-05 19:12:53,017 - aiohttp.access - INFO - 127.0.0.1 [05/Jun/2020:11:11:37 +0000] "POST / HTTP/1.1" 500 244 "-" "GitHub-Hookshot/8c87336"
2020-06-05 19:22:10,797 - aiohttp.access - INFO - 127.0.0.1 [05/Jun/2020:11:22:08 +0000] "POST / HTTP/1.1" 200 168 "-" "GitHub-Hookshot/8c87336"
2020-06-05 19:22:19,595 - event - ERROR - 68 Not Trigger CI.
2020-06-05 19:22:21,255 - event - ERROR - 68 Not Follow Template.
2020-06-05 19:22:21,940 - aiohttp.access - INFO - 127.0.0.1 [05/Jun/2020:11:22:20 +0000] "POST / HTTP/1.1" 200 168 "-" "GitHub-Hookshot/8c87336"
2020-06-05 19:22:22,211 - aiohttp.access - INFO - 127.0.0.1 [05/Jun/2020:11:22:16 +0000] "POST / HTTP/1.1" 200 168 "-" "GitHub-Hookshot/8c87336"
2020-06-05 19:22:23,551 - aiohttp.access - INFO - 127.0.0.1 [05/Jun/2020:11:22:22 +0000] "POST / HTTP/1.1" 200 168 "-" "GitHub-Hookshot/8c87336"
2020-06-05 19:22:24,215 - aiohttp.access - INFO - 127.0.0.1 [05/Jun/2020:11:22:21 +0000] "POST / HTTP/1.1" 200 168 "-" "GitHub-Hookshot/8c87336"
2020-06-05 19:22:25,750 - aiohttp.access - INFO - 127.0.0.1 [05/Jun/2020:11:22:24 +0000] "POST / HTTP/1.1" 200 168 "-" "GitHub-Hookshot/8c87336"
2020-06-05 19:26:34,789 - aiohttp.access - INFO - 127.0.0.1 [05/Jun/2020:11:26:34 +0000] "GET /_debugtoolbar HTTP/1.1" 404 172 "-" "Mozilla/5.0 (Macintosh; Intel Mac OS X 10_14_6) AppleWebKit/537.36 (KHTML, like Gecko) Chrome/83.0.4103.61 Safari/537.36"
2020-06-05 19:26:37,533 - aiohttp.access - INFO - 127.0.0.1 [05/Jun/2020:11:26:37 +0000] "GET /_debugtoolbar HTTP/1.1" 404 172 "-" "Mozilla/5.0 (Macintosh; Intel Mac OS X 10_14_6) AppleWebKit/537.36 (KHTML, like Gecko) Chrome/83.0.4103.61 Safari/537.36"
2020-06-05 19:52:19,759 - aiohttp.access - INFO - 127.0.0.1 [05/Jun/2020:11:52:18 +0000] "POST / HTTP/1.1" 200 168 "-" "GitHub-Hookshot/8c87336"

































2020-06-08 10:39:25,884 - aiohttp.access - INFO - 127.0.0.1 [08/Jun/2020:02:39:24 +0000] "POST / HTTP/1.1" 200 168 "-" "GitHub-Hookshot/f1dd063"
2020-06-08 10:39:56,603 - event - ERROR - 70 Not Trigger CI.
2020-06-08 10:39:58,258 - event - ERROR - 70 Not Follow Template.
2020-06-08 10:39:58,960 - aiohttp.access - INFO - 127.0.0.1 [08/Jun/2020:02:39:57 +0000] "POST / HTTP/1.1" 200 168 "-" "GitHub-Hookshot/f1dd063"
2020-06-08 10:39:59,246 - aiohttp.access - INFO - 127.0.0.1 [08/Jun/2020:02:39:53 +0000] "POST / HTTP/1.1" 200 168 "-" "GitHub-Hookshot/f1dd063"
2020-06-08 10:40:00,635 - aiohttp.access - INFO - 127.0.0.1 [08/Jun/2020:02:39:59 +0000] "POST / HTTP/1.1" 200 168 "-" "GitHub-Hookshot/f1dd063"
2020-06-08 10:40:01,529 - aiohttp.access - INFO - 127.0.0.1 [08/Jun/2020:02:39:58 +0000] "POST / HTTP/1.1" 200 168 "-" "GitHub-Hookshot/f1dd063"
2020-06-08 10:40:02,950 - aiohttp.access - INFO - 127.0.0.1 [08/Jun/2020:02:40:01 +0000] "POST / HTTP/1.1" 200 168 "-" "GitHub-Hookshot/f1dd063"







2020-06-08 10:50:05,496 - aiohttp.access - INFO - 127.0.0.1 [08/Jun/2020:02:50:03 +0000] "POST / HTTP/1.1" 200 168 "-" "GitHub-Hookshot/f1dd063"
2020-06-08 10:50:50,929 - aiohttp.access - INFO - 127.0.0.1 [08/Jun/2020:02:50:49 +0000] "POST / HTTP/1.1" 200 168 "-" "GitHub-Hookshot/f1dd063"
2020-06-08 10:50:56,370 - event - INFO - 74 Trigger CI Successful.
2020-06-08 10:50:58,012 - event - ERROR - 74 Not Follow Template.
2020-06-08 10:50:58,669 - aiohttp.access - INFO - 127.0.0.1 [08/Jun/2020:02:50:57 +0000] "POST / HTTP/1.1" 200 168 "-" "GitHub-Hookshot/f1dd063"
2020-06-08 10:50:59,042 - aiohttp.access - INFO - 127.0.0.1 [08/Jun/2020:02:50:53 +0000] "POST / HTTP/1.1" 200 168 "-" "GitHub-Hookshot/f1dd063"
2020-06-08 10:51:00,314 - aiohttp.access - INFO - 127.0.0.1 [08/Jun/2020:02:50:58 +0000] "POST / HTTP/1.1" 200 168 "-" "GitHub-Hookshot/f1dd063"
2020-06-08 10:51:00,839 - aiohttp.access - INFO - 127.0.0.1 [08/Jun/2020:02:50:57 +0000] "POST / HTTP/1.1" 200 168 "-" "GitHub-Hookshot/f1dd063"
2020-06-08 10:51:02,432 - aiohttp.access - INFO - 127.0.0.1 [08/Jun/2020:02:51:00 +0000] "POST / HTTP/1.1" 200 168 "-" "GitHub-Hookshot/f1dd063"
2020-06-09 12:43:39,433 - event - ERROR - 76 Not Trigger CI.
2020-06-09 12:43:41,283 - event - ERROR - 76 Not Follow Template.
2020-06-09 12:43:42,250 - aiohttp.access - INFO - 127.0.0.1 [09/Jun/2020:04:43:36 +0000] "POST / HTTP/1.1" 200 168 "-" "GitHub-Hookshot/f1dd063"
2020-06-09 12:43:42,262 - aiohttp.access - INFO - 127.0.0.1 [09/Jun/2020:04:43:40 +0000] "POST / HTTP/1.1" 200 168 "-" "GitHub-Hookshot/f1dd063"
2020-06-09 12:43:44,014 - aiohttp.access - INFO - 127.0.0.1 [09/Jun/2020:04:43:42 +0000] "POST / HTTP/1.1" 200 168 "-" "GitHub-Hookshot/f1dd063"
2020-06-09 12:43:45,791 - aiohttp.access - INFO - 127.0.0.1 [09/Jun/2020:04:43:41 +0000] "POST / HTTP/1.1" 200 168 "-" "GitHub-Hookshot/f1dd063"
2020-06-09 12:43:47,622 - aiohttp.access - INFO - 127.0.0.1 [09/Jun/2020:04:43:46 +0000] "POST / HTTP/1.1" 200 168 "-" "GitHub-Hookshot/f1dd063"
2020-06-10 11:46:46,080 - aiohttp.server - ERROR - Error handling request
Traceback (most recent call last):
  File "/Users/litianrun/anaconda3/lib/python3.7/site-packages/aiohttp/web_protocol.py", line 418, in start
    resp = await task
  File "/Users/litianrun/anaconda3/lib/python3.7/site-packages/aiohttp/web_app.py", line 458, in _handle
    resp = await handler(request)
  File "__main__.py", line 24, in main
    jwt = get_jwt(app_id)
  File "/Users/litianrun/Desktop/Paddle-bot/webservice/utils/auth.py", line 11, in get_jwt
    pem_file = open(path_to_private_key, "rt").read()
FileNotFoundError: [Errno 2] No such file or directory: '/Users/litianrun/Desktop/Paddle-bot/pbot-demo.2020-06-03.private-key.pem'
2020-06-10 11:46:46,100 - aiohttp.access - INFO - 127.0.0.1 [10/Jun/2020:03:46:46 +0000] "POST / HTTP/1.1" 500 244 "-" "GitHub-Hookshot/022660f"
2020-06-22 14:12:53,055 - aiohttp.server - ERROR - Error handling request
Traceback (most recent call last):
  File "/Library/Frameworks/Python.framework/Versions/3.7/lib/python3.7/site-packages/aiohttp/web_protocol.py", line 418, in start
    resp = await task
  File "/Library/Frameworks/Python.framework/Versions/3.7/lib/python3.7/site-packages/aiohttp/web_app.py", line 458, in _handle
    resp = await handler(request)
  File "/Users/randy/Desktop/Paddle-bot/webservice/__main__.py", line 21, in main
    event = sansio.Event.from_http(request.headers, body, secret=secret)
  File "/Library/Frameworks/Python.framework/Versions/3.7/lib/python3.7/site-packages/gidgethub/sansio.py", line 119, in from_http
    raise ValidationFailure("secret not provided")
gidgethub.ValidationFailure: secret not provided
2020-06-22 14:12:53,061 - aiohttp.access - INFO - 127.0.0.1 [22/Jun/2020:06:12:53 +0000] "POST / HTTP/1.1" 500 244 "-" "GitHub-Hookshot/7004fb2"
2020-06-22 14:13:43,197 - aiohttp.server - ERROR - Error handling request
Traceback (most recent call last):
  File "/Library/Frameworks/Python.framework/Versions/3.7/lib/python3.7/site-packages/aiohttp/web_protocol.py", line 418, in start
    resp = await task
  File "/Library/Frameworks/Python.framework/Versions/3.7/lib/python3.7/site-packages/aiohttp/web_app.py", line 458, in _handle
    resp = await handler(request)
  File "/Users/randy/Desktop/Paddle-bot/webservice/__main__.py", line 21, in main
    event = sansio.Event.from_http(request.headers, body, secret=secret)
  File "/Library/Frameworks/Python.framework/Versions/3.7/lib/python3.7/site-packages/gidgethub/sansio.py", line 119, in from_http
    raise ValidationFailure("secret not provided")
gidgethub.ValidationFailure: secret not provided
2020-06-22 14:13:43,197 - aiohttp.access - INFO - 127.0.0.1 [22/Jun/2020:06:13:43 +0000] "POST / HTTP/1.1" 500 244 "-" "GitHub-Hookshot/7004fb2"
2020-06-22 14:14:11,282 - aiohttp.server - ERROR - Error handling request
Traceback (most recent call last):
  File "/Library/Frameworks/Python.framework/Versions/3.7/lib/python3.7/site-packages/aiohttp/web_protocol.py", line 418, in start
    resp = await task
  File "/Library/Frameworks/Python.framework/Versions/3.7/lib/python3.7/site-packages/aiohttp/web_app.py", line 458, in _handle
    resp = await handler(request)
  File "/Users/randy/Desktop/Paddle-bot/webservice/__main__.py", line 21, in main
    event = sansio.Event.from_http(request.headers, body, secret=secret)
  File "/Library/Frameworks/Python.framework/Versions/3.7/lib/python3.7/site-packages/gidgethub/sansio.py", line 119, in from_http
    raise ValidationFailure("secret not provided")
gidgethub.ValidationFailure: secret not provided
2020-06-22 14:14:11,283 - aiohttp.access - INFO - 127.0.0.1 [22/Jun/2020:06:14:11 +0000] "POST / HTTP/1.1" 500 244 "-" "GitHub-Hookshot/7004fb2"
2020-06-22 14:20:57,388 - aiohttp.server - ERROR - Error handling request
Traceback (most recent call last):
  File "/Library/Frameworks/Python.framework/Versions/3.7/lib/python3.7/site-packages/aiohttp/web_protocol.py", line 418, in start
    resp = await task
  File "/Library/Frameworks/Python.framework/Versions/3.7/lib/python3.7/site-packages/aiohttp/web_app.py", line 458, in _handle
    resp = await handler(request)
  File "__main__.py", line 21, in main
    event = sansio.Event.from_http(request.headers, body, secret=secret)
  File "/Library/Frameworks/Python.framework/Versions/3.7/lib/python3.7/site-packages/gidgethub/sansio.py", line 120, in from_http
    validate_event(body, signature=headers["x-hub-signature"], secret=secret)
  File "/Library/Frameworks/Python.framework/Versions/3.7/lib/python3.7/site-packages/gidgethub/sansio.py", line 81, in validate_event
    raise ValidationFailure("payload's signature does not align " "with the secret")
gidgethub.ValidationFailure: payload's signature does not align with the secret
2020-06-22 14:20:57,397 - aiohttp.access - INFO - 127.0.0.1 [22/Jun/2020:06:20:57 +0000] "POST / HTTP/1.1" 500 244 "-" "GitHub-Hookshot/7004fb2"
2020-06-22 14:21:17,778 - aiohttp.server - ERROR - Error handling request
Traceback (most recent call last):
  File "/Library/Frameworks/Python.framework/Versions/3.7/lib/python3.7/site-packages/aiohttp/web_protocol.py", line 418, in start
    resp = await task
  File "/Library/Frameworks/Python.framework/Versions/3.7/lib/python3.7/site-packages/aiohttp/web_app.py", line 458, in _handle
    resp = await handler(request)
  File "__main__.py", line 21, in main
    event = sansio.Event.from_http(request.headers, body, secret=secret)
  File "/Library/Frameworks/Python.framework/Versions/3.7/lib/python3.7/site-packages/gidgethub/sansio.py", line 120, in from_http
    validate_event(body, signature=headers["x-hub-signature"], secret=secret)
  File "/Library/Frameworks/Python.framework/Versions/3.7/lib/python3.7/site-packages/gidgethub/sansio.py", line 81, in validate_event
    raise ValidationFailure("payload's signature does not align " "with the secret")
gidgethub.ValidationFailure: payload's signature does not align with the secret
2020-06-22 14:21:17,780 - aiohttp.access - INFO - 127.0.0.1 [22/Jun/2020:06:21:17 +0000] "POST / HTTP/1.1" 500 244 "-" "GitHub-Hookshot/7004fb2"
2020-06-22 14:21:34,004 - aiohttp.server - ERROR - Error handling request
Traceback (most recent call last):
  File "/Library/Frameworks/Python.framework/Versions/3.7/lib/python3.7/site-packages/aiohttp/web_protocol.py", line 418, in start
    resp = await task
  File "/Library/Frameworks/Python.framework/Versions/3.7/lib/python3.7/site-packages/aiohttp/web_app.py", line 458, in _handle
    resp = await handler(request)
  File "__main__.py", line 21, in main
    event = sansio.Event.from_http(request.headers, body, secret=secret)
  File "/Library/Frameworks/Python.framework/Versions/3.7/lib/python3.7/site-packages/gidgethub/sansio.py", line 120, in from_http
    validate_event(body, signature=headers["x-hub-signature"], secret=secret)
  File "/Library/Frameworks/Python.framework/Versions/3.7/lib/python3.7/site-packages/gidgethub/sansio.py", line 81, in validate_event
    raise ValidationFailure("payload's signature does not align " "with the secret")
gidgethub.ValidationFailure: payload's signature does not align with the secret
2020-06-22 14:21:34,005 - aiohttp.access - INFO - 127.0.0.1 [22/Jun/2020:06:21:34 +0000] "POST / HTTP/1.1" 500 244 "-" "GitHub-Hookshot/7004fb2"
2020-06-22 14:37:14,162 - asyncio - ERROR - SSL handshake failed on verifying the certificate
protocol: <asyncio.sslproto.SSLProtocol object at 0x10905b240>
transport: <_SelectorSocketTransport fd=12 read=polling write=<idle, bufsize=0>>
Traceback (most recent call last):
  File "/Library/Frameworks/Python.framework/Versions/3.7/lib/python3.7/asyncio/sslproto.py", line 625, in _on_handshake_complete
    raise handshake_exc
  File "/Library/Frameworks/Python.framework/Versions/3.7/lib/python3.7/asyncio/sslproto.py", line 189, in feed_ssldata
    self._sslobj.do_handshake()
  File "/Library/Frameworks/Python.framework/Versions/3.7/lib/python3.7/ssl.py", line 763, in do_handshake
    self._sslobj.do_handshake()
ssl.SSLCertVerificationError: [SSL: CERTIFICATE_VERIFY_FAILED] certificate verify failed: unable to get local issuer certificate (_ssl.c:1056)
2020-06-22 14:37:14,167 - asyncio - ERROR - SSL error in data received
protocol: <asyncio.sslproto.SSLProtocol object at 0x10905b240>
transport: <_SelectorSocketTransport closing fd=12 read=idle write=<idle, bufsize=0>>
Traceback (most recent call last):
  File "/Library/Frameworks/Python.framework/Versions/3.7/lib/python3.7/asyncio/sslproto.py", line 526, in data_received
    ssldata, appdata = self._sslpipe.feed_ssldata(data)
  File "/Library/Frameworks/Python.framework/Versions/3.7/lib/python3.7/asyncio/sslproto.py", line 189, in feed_ssldata
    self._sslobj.do_handshake()
  File "/Library/Frameworks/Python.framework/Versions/3.7/lib/python3.7/ssl.py", line 763, in do_handshake
    self._sslobj.do_handshake()
ssl.SSLCertVerificationError: [SSL: CERTIFICATE_VERIFY_FAILED] certificate verify failed: unable to get local issuer certificate (_ssl.c:1056)
2020-06-22 14:37:14,170 - aiohttp.access - INFO - 127.0.0.1 [22/Jun/2020:06:37:12 +0000] "POST / HTTP/1.1" 200 168 "-" "GitHub-Hookshot/7004fb2"
2020-06-22 14:37:23,080 - asyncio - ERROR - SSL handshake failed on verifying the certificate
protocol: <asyncio.sslproto.SSLProtocol object at 0x109109f98>
transport: <_SelectorSocketTransport fd=12 read=polling write=<idle, bufsize=0>>
Traceback (most recent call last):
  File "/Library/Frameworks/Python.framework/Versions/3.7/lib/python3.7/asyncio/sslproto.py", line 625, in _on_handshake_complete
    raise handshake_exc
  File "/Library/Frameworks/Python.framework/Versions/3.7/lib/python3.7/asyncio/sslproto.py", line 189, in feed_ssldata
    self._sslobj.do_handshake()
  File "/Library/Frameworks/Python.framework/Versions/3.7/lib/python3.7/ssl.py", line 763, in do_handshake
    self._sslobj.do_handshake()
ssl.SSLCertVerificationError: [SSL: CERTIFICATE_VERIFY_FAILED] certificate verify failed: unable to get local issuer certificate (_ssl.c:1056)
2020-06-22 14:37:23,081 - asyncio - ERROR - SSL error in data received
protocol: <asyncio.sslproto.SSLProtocol object at 0x109109f98>
transport: <_SelectorSocketTransport closing fd=12 read=idle write=<idle, bufsize=0>>
Traceback (most recent call last):
  File "/Library/Frameworks/Python.framework/Versions/3.7/lib/python3.7/asyncio/sslproto.py", line 526, in data_received
    ssldata, appdata = self._sslpipe.feed_ssldata(data)
  File "/Library/Frameworks/Python.framework/Versions/3.7/lib/python3.7/asyncio/sslproto.py", line 189, in feed_ssldata
    self._sslobj.do_handshake()
  File "/Library/Frameworks/Python.framework/Versions/3.7/lib/python3.7/ssl.py", line 763, in do_handshake
    self._sslobj.do_handshake()
ssl.SSLCertVerificationError: [SSL: CERTIFICATE_VERIFY_FAILED] certificate verify failed: unable to get local issuer certificate (_ssl.c:1056)
2020-06-22 14:37:23,082 - aiohttp.access - INFO - 127.0.0.1 [22/Jun/2020:06:37:22 +0000] "POST / HTTP/1.1" 200 168 "-" "GitHub-Hookshot/7004fb2"
2020-06-22 14:43:55,337 - asyncio - ERROR - SSL handshake failed on verifying the certificate
protocol: <asyncio.sslproto.SSLProtocol object at 0x109121908>
transport: <_SelectorSocketTransport fd=12 read=polling write=<idle, bufsize=0>>
Traceback (most recent call last):
  File "/Library/Frameworks/Python.framework/Versions/3.7/lib/python3.7/asyncio/sslproto.py", line 625, in _on_handshake_complete
    raise handshake_exc
  File "/Library/Frameworks/Python.framework/Versions/3.7/lib/python3.7/asyncio/sslproto.py", line 189, in feed_ssldata
    self._sslobj.do_handshake()
  File "/Library/Frameworks/Python.framework/Versions/3.7/lib/python3.7/ssl.py", line 763, in do_handshake
    self._sslobj.do_handshake()
ssl.SSLCertVerificationError: [SSL: CERTIFICATE_VERIFY_FAILED] certificate verify failed: unable to get local issuer certificate (_ssl.c:1056)
2020-06-22 14:43:55,339 - asyncio - ERROR - SSL error in data received
protocol: <asyncio.sslproto.SSLProtocol object at 0x109121908>
transport: <_SelectorSocketTransport closing fd=12 read=idle write=<idle, bufsize=0>>
Traceback (most recent call last):
  File "/Library/Frameworks/Python.framework/Versions/3.7/lib/python3.7/asyncio/sslproto.py", line 526, in data_received
    ssldata, appdata = self._sslpipe.feed_ssldata(data)
  File "/Library/Frameworks/Python.framework/Versions/3.7/lib/python3.7/asyncio/sslproto.py", line 189, in feed_ssldata
    self._sslobj.do_handshake()
  File "/Library/Frameworks/Python.framework/Versions/3.7/lib/python3.7/ssl.py", line 763, in do_handshake
    self._sslobj.do_handshake()
ssl.SSLCertVerificationError: [SSL: CERTIFICATE_VERIFY_FAILED] certificate verify failed: unable to get local issuer certificate (_ssl.c:1056)
2020-06-22 14:43:55,344 - aiohttp.access - INFO - 127.0.0.1 [22/Jun/2020:06:43:54 +0000] "POST / HTTP/1.1" 200 168 "-" "GitHub-Hookshot/7004fb2"
